[2025-08-28T08:21:09.028+0000] {taskinstance.py:1956} INFO - Dependencies all met for dep_context=non-requeueable deps ti=<TaskInstance: etl_pipeline.extract manual__2025-08-28T08:21:05.809880+00:00 [queued]>
[2025-08-28T08:21:09.041+0000] {taskinstance.py:1956} INFO - Dependencies all met for dep_context=requeueable deps ti=<TaskInstance: etl_pipeline.extract manual__2025-08-28T08:21:05.809880+00:00 [queued]>
[2025-08-28T08:21:09.042+0000] {taskinstance.py:2170} INFO - Starting attempt 1 of 1
[2025-08-28T08:21:09.065+0000] {taskinstance.py:2191} INFO - Executing <Task(PythonOperator): extract> on 2025-08-28 08:21:05.809880+00:00
[2025-08-28T08:21:09.079+0000] {standard_task_runner.py:60} INFO - Started process 478 to run task
[2025-08-28T08:21:09.084+0000] {standard_task_runner.py:87} INFO - Running: ['***', 'tasks', 'run', 'etl_pipeline', 'extract', 'manual__2025-08-28T08:21:05.809880+00:00', '--job-id', '3', '--raw', '--subdir', 'DAGS_FOLDER/etl_pipeline.py', '--cfg-path', '/tmp/tmpft8f2h1s']
[2025-08-28T08:21:09.104+0000] {standard_task_runner.py:88} INFO - Job 3: Subtask extract
[2025-08-28T08:21:09.225+0000] {logging_mixin.py:188} WARNING - /home/***/.local/lib/python3.8/site-packages/***/settings.py:194 DeprecationWarning: The sql_alchemy_conn option in [core] has been moved to the sql_alchemy_conn option in [database] - the old setting has been used, but please update your config.
[2025-08-28T08:21:09.552+0000] {task_command.py:423} INFO - Running <TaskInstance: etl_pipeline.extract manual__2025-08-28T08:21:05.809880+00:00 [running]> on host dd18df0f367e
[2025-08-28T08:21:09.963+0000] {taskinstance.py:2480} INFO - Exporting env vars: AIRFLOW_CTX_DAG_OWNER='***' AIRFLOW_CTX_DAG_ID='etl_pipeline' AIRFLOW_CTX_TASK_ID='extract' AIRFLOW_CTX_EXECUTION_DATE='2025-08-28T08:21:05.809880+00:00' AIRFLOW_CTX_TRY_NUMBER='1' AIRFLOW_CTX_DAG_RUN_ID='manual__2025-08-28T08:21:05.809880+00:00'
[2025-08-28T08:21:09.974+0000] {taskinstance.py:2698} ERROR - Task failed with exception
Traceback (most recent call last):
  File "/home/airflow/.local/lib/python3.8/site-packages/airflow/models/taskinstance.py", line 433, in _execute_task
    result = execute_callable(context=context, **execute_callable_kwargs)
  File "/home/airflow/.local/lib/python3.8/site-packages/airflow/operators/python.py", line 199, in execute
    return_value = self.execute_callable()
  File "/home/airflow/.local/lib/python3.8/site-packages/airflow/operators/python.py", line 216, in execute_callable
    return self.python_callable(*self.op_args, **self.op_kwargs)
  File "/opt/airflow/dags/etl_pipeline.py", line 7, in fake_extract
    conf = context["dag_run"].conf or {}
NameError: name 'context' is not defined
[2025-08-28T08:21:10.012+0000] {taskinstance.py:1138} INFO - Marking task as FAILED. dag_id=etl_pipeline, task_id=extract, execution_date=20250828T082105, start_date=20250828T082109, end_date=20250828T082110
[2025-08-28T08:21:10.053+0000] {standard_task_runner.py:107} ERROR - Failed to execute job 3 for task extract (name 'context' is not defined; 478)
[2025-08-28T08:21:10.095+0000] {local_task_job_runner.py:234} INFO - Task exited with return code 1
[2025-08-28T08:21:10.188+0000] {taskinstance.py:3280} INFO - 0 downstream tasks scheduled from follow-on schedule check
