[2025-09-01T09:08:01.817+0000] {taskinstance.py:1956} INFO - Dependencies all met for dep_context=non-requeueable deps ti=<TaskInstance: etl_pipeline.load manual__2025-09-01T09:07:49.071268+00:00 [queued]>
[2025-09-01T09:08:01.828+0000] {taskinstance.py:1956} INFO - Dependencies all met for dep_context=requeueable deps ti=<TaskInstance: etl_pipeline.load manual__2025-09-01T09:07:49.071268+00:00 [queued]>
[2025-09-01T09:08:01.828+0000] {taskinstance.py:2170} INFO - Starting attempt 1 of 1
[2025-09-01T09:08:01.844+0000] {taskinstance.py:2191} INFO - Executing <Task(PythonOperator): load> on 2025-09-01 09:07:49.071268+00:00
[2025-09-01T09:08:01.856+0000] {standard_task_runner.py:60} INFO - Started process 581 to run task
[2025-09-01T09:08:01.863+0000] {standard_task_runner.py:87} INFO - Running: ['***', 'tasks', 'run', 'etl_pipeline', 'load', 'manual__2025-09-01T09:07:49.071268+00:00', '--job-id', '8', '--raw', '--subdir', 'DAGS_FOLDER/etl_pipeline.py', '--cfg-path', '/tmp/tmpop9vwv32']
[2025-09-01T09:08:01.881+0000] {standard_task_runner.py:88} INFO - Job 8: Subtask load
[2025-09-01T09:08:02.040+0000] {logging_mixin.py:188} WARNING - /home/***/.local/lib/python3.8/site-packages/***/settings.py:194 DeprecationWarning: The sql_alchemy_conn option in [core] has been moved to the sql_alchemy_conn option in [database] - the old setting has been used, but please update your config.
[2025-09-01T09:08:02.151+0000] {task_command.py:423} INFO - Running <TaskInstance: etl_pipeline.load manual__2025-09-01T09:07:49.071268+00:00 [running]> on host f8a9cd7e9422
[2025-09-01T09:08:02.312+0000] {taskinstance.py:2480} INFO - Exporting env vars: AIRFLOW_CTX_DAG_OWNER='***' AIRFLOW_CTX_DAG_ID='etl_pipeline' AIRFLOW_CTX_TASK_ID='load' AIRFLOW_CTX_EXECUTION_DATE='2025-09-01T09:07:49.071268+00:00' AIRFLOW_CTX_TRY_NUMBER='1' AIRFLOW_CTX_DAG_RUN_ID='manual__2025-09-01T09:07:49.071268+00:00'
[2025-09-01T09:08:02.328+0000] {etl_pipeline.py:158} INFO - Reading processed file /tmp/etl_processed/processed_6ad53c99-a303-4e5b-9063-9faeb6222861_applicants.csv
[2025-09-01T09:08:02.350+0000] {etl_pipeline.py:182} INFO - Inserting 20 rows into ClickHouse table applicants
[2025-09-01T09:08:02.388+0000] {etl_pipeline.py:185} ERROR - Failed to insert into ClickHouse: Code: 53. Type mismatch in VALUES section. Repeat query with types_check=True for detailed info. Column applicant_id: required argument is not an integer
Traceback (most recent call last):
  File "/home/airflow/.local/lib/python3.8/site-packages/clickhouse_driver/columns/base.py", line 203, in write_items
    buf.write(s.pack(*items))
struct.error: required argument is not an integer

During handling of the above exception, another exception occurred:

Traceback (most recent call last):
  File "/home/airflow/.local/lib/python3.8/site-packages/clickhouse_driver/columns/service.py", line 167, in write_column
    column.write_data(items, buf)
  File "/home/airflow/.local/lib/python3.8/site-packages/clickhouse_driver/columns/base.py", line 145, in write_data
    self._write_data(items, buf)
  File "/home/airflow/.local/lib/python3.8/site-packages/clickhouse_driver/columns/base.py", line 149, in _write_data
    self.write_items(prepared, buf)
  File "/home/airflow/.local/lib/python3.8/site-packages/clickhouse_driver/columns/base.py", line 206, in write_items
    raise exceptions.StructPackException(e)
clickhouse_driver.columns.exceptions.StructPackException: required argument is not an integer

During handling of the above exception, another exception occurred:

Traceback (most recent call last):
  File "/opt/airflow/dags/etl_pipeline.py", line 183, in perform_load
    client.execute(insert_sql, records)
  File "/home/airflow/.local/lib/python3.8/site-packages/clickhouse_driver/client.py", line 376, in execute
    rv = self.process_insert_query(
  File "/home/airflow/.local/lib/python3.8/site-packages/clickhouse_driver/client.py", line 607, in process_insert_query
    rv = self.send_data(sample_block, data,
  File "/home/airflow/.local/lib/python3.8/site-packages/clickhouse_driver/client.py", line 660, in send_data
    self.connection.send_data(block)
  File "/home/airflow/.local/lib/python3.8/site-packages/clickhouse_driver/connection.py", line 688, in send_data
    self.block_out.write(block)
  File "/home/airflow/.local/lib/python3.8/site-packages/clickhouse_driver/streams/native.py", line 48, in write
    write_column(self.context, col_name, col_type, items,
  File "/home/airflow/.local/lib/python3.8/site-packages/clickhouse_driver/columns/service.py", line 179, in write_column
    raise errors.TypeMismatchError(
clickhouse_driver.errors.TypeMismatchError: Code: 53. Type mismatch in VALUES section. Repeat query with types_check=True for detailed info. Column applicant_id: required argument is not an integer
[2025-09-01T09:08:02.419+0000] {taskinstance.py:2698} ERROR - Task failed with exception
Traceback (most recent call last):
  File "/home/airflow/.local/lib/python3.8/site-packages/clickhouse_driver/columns/base.py", line 203, in write_items
    buf.write(s.pack(*items))
struct.error: required argument is not an integer

During handling of the above exception, another exception occurred:

Traceback (most recent call last):
  File "/home/airflow/.local/lib/python3.8/site-packages/clickhouse_driver/columns/service.py", line 167, in write_column
    column.write_data(items, buf)
  File "/home/airflow/.local/lib/python3.8/site-packages/clickhouse_driver/columns/base.py", line 145, in write_data
    self._write_data(items, buf)
  File "/home/airflow/.local/lib/python3.8/site-packages/clickhouse_driver/columns/base.py", line 149, in _write_data
    self.write_items(prepared, buf)
  File "/home/airflow/.local/lib/python3.8/site-packages/clickhouse_driver/columns/base.py", line 206, in write_items
    raise exceptions.StructPackException(e)
clickhouse_driver.columns.exceptions.StructPackException: required argument is not an integer

During handling of the above exception, another exception occurred:

Traceback (most recent call last):
  File "/opt/airflow/dags/etl_pipeline.py", line 183, in perform_load
    client.execute(insert_sql, records)
  File "/home/airflow/.local/lib/python3.8/site-packages/clickhouse_driver/client.py", line 376, in execute
    rv = self.process_insert_query(
  File "/home/airflow/.local/lib/python3.8/site-packages/clickhouse_driver/client.py", line 607, in process_insert_query
    rv = self.send_data(sample_block, data,
  File "/home/airflow/.local/lib/python3.8/site-packages/clickhouse_driver/client.py", line 660, in send_data
    self.connection.send_data(block)
  File "/home/airflow/.local/lib/python3.8/site-packages/clickhouse_driver/connection.py", line 688, in send_data
    self.block_out.write(block)
  File "/home/airflow/.local/lib/python3.8/site-packages/clickhouse_driver/streams/native.py", line 48, in write
    write_column(self.context, col_name, col_type, items,
  File "/home/airflow/.local/lib/python3.8/site-packages/clickhouse_driver/columns/service.py", line 179, in write_column
    raise errors.TypeMismatchError(
clickhouse_driver.errors.TypeMismatchError: Code: 53. Type mismatch in VALUES section. Repeat query with types_check=True for detailed info. Column applicant_id: required argument is not an integer

The above exception was the direct cause of the following exception:

Traceback (most recent call last):
  File "/home/airflow/.local/lib/python3.8/site-packages/airflow/models/taskinstance.py", line 433, in _execute_task
    result = execute_callable(context=context, **execute_callable_kwargs)
  File "/home/airflow/.local/lib/python3.8/site-packages/airflow/operators/python.py", line 199, in execute
    return_value = self.execute_callable()
  File "/home/airflow/.local/lib/python3.8/site-packages/airflow/operators/python.py", line 216, in execute_callable
    return self.python_callable(*self.op_args, **self.op_kwargs)
  File "/opt/airflow/dags/etl_pipeline.py", line 235, in run_load
    perform_load(processed_path=processed_path)
  File "/opt/airflow/dags/etl_pipeline.py", line 186, in perform_load
    raise RuntimeError(f"Load failed for {processed_path} into {CLICKHOUSE_TABLE}") from e
RuntimeError: Load failed for /tmp/etl_processed/processed_6ad53c99-a303-4e5b-9063-9faeb6222861_applicants.csv into applicants
[2025-09-01T09:08:02.441+0000] {taskinstance.py:1138} INFO - Marking task as FAILED. dag_id=etl_pipeline, task_id=load, execution_date=20250901T090749, start_date=20250901T090801, end_date=20250901T090802
[2025-09-01T09:08:02.465+0000] {standard_task_runner.py:107} ERROR - Failed to execute job 8 for task load (Load failed for /tmp/etl_processed/processed_6ad53c99-a303-4e5b-9063-9faeb6222861_applicants.csv into applicants; 581)
[2025-09-01T09:08:02.490+0000] {local_task_job_runner.py:234} INFO - Task exited with return code 1
[2025-09-01T09:08:02.541+0000] {taskinstance.py:3280} INFO - 0 downstream tasks scheduled from follow-on schedule check
