[2025-09-02T06:33:29.639+0000] {taskinstance.py:1956} INFO - Dependencies all met for dep_context=non-requeueable deps ti=<TaskInstance: etl_pipeline.extract manual__2025-09-02T06:33:06.127601+00:00 [queued]>
[2025-09-02T06:33:29.657+0000] {taskinstance.py:1956} INFO - Dependencies all met for dep_context=requeueable deps ti=<TaskInstance: etl_pipeline.extract manual__2025-09-02T06:33:06.127601+00:00 [queued]>
[2025-09-02T06:33:29.658+0000] {taskinstance.py:2170} INFO - Starting attempt 1 of 1
[2025-09-02T06:33:29.723+0000] {taskinstance.py:2191} INFO - Executing <Task(PythonOperator): extract> on 2025-09-02 06:33:06.127601+00:00
[2025-09-02T06:33:29.767+0000] {standard_task_runner.py:60} INFO - Started process 1033 to run task
[2025-09-02T06:33:29.787+0000] {standard_task_runner.py:87} INFO - Running: ['***', 'tasks', 'run', 'etl_pipeline', 'extract', 'manual__2025-09-02T06:33:06.127601+00:00', '--job-id', '23', '--raw', '--subdir', 'DAGS_FOLDER/etl_pipeline.py', '--cfg-path', '/tmp/tmppiksgdwa']
[2025-09-02T06:33:29.804+0000] {standard_task_runner.py:88} INFO - Job 23: Subtask extract
[2025-09-02T06:33:29.909+0000] {logging_mixin.py:188} WARNING - /home/***/.local/lib/python3.8/site-packages/***/settings.py:194 DeprecationWarning: The sql_alchemy_conn option in [core] has been moved to the sql_alchemy_conn option in [database] - the old setting has been used, but please update your config.
[2025-09-02T06:33:30.163+0000] {task_command.py:423} INFO - Running <TaskInstance: etl_pipeline.extract manual__2025-09-02T06:33:06.127601+00:00 [running]> on host f1d436f67367
[2025-09-02T06:33:30.443+0000] {taskinstance.py:2480} INFO - Exporting env vars: AIRFLOW_CTX_DAG_OWNER='***' AIRFLOW_CTX_DAG_ID='etl_pipeline' AIRFLOW_CTX_TASK_ID='extract' AIRFLOW_CTX_EXECUTION_DATE='2025-09-02T06:33:06.127601+00:00' AIRFLOW_CTX_TRY_NUMBER='1' AIRFLOW_CTX_DAG_RUN_ID='manual__2025-09-02T06:33:06.127601+00:00'
[2025-09-02T06:33:31.064+0000] {etl_pipeline.py:73} INFO - Downloading s3://landing/2025/09/02/58578ad7-7d53-4d5b-8543-8cc0699b601f_applicants.csv -> /tmp/etl_staging/58578ad7-7d53-4d5b-8543-8cc0699b601f_applicants.csv
[2025-09-02T06:33:31.347+0000] {etl_pipeline.py:76} ERROR - Failed to download file from MinIO: An error occurred (404) when calling the HeadObject operation: Not Found
Traceback (most recent call last):
  File "/opt/airflow/dags/etl_pipeline.py", line 74, in perform_extract
    client.download_file(MINIO_LANDING_BUCKET, file_path, staging_path)
  File "/home/airflow/.local/lib/python3.8/site-packages/boto3/s3/inject.py", line 192, in download_file
    return transfer.download_file(
  File "/home/airflow/.local/lib/python3.8/site-packages/boto3/s3/transfer.py", line 405, in download_file
    future.result()
  File "/home/airflow/.local/lib/python3.8/site-packages/s3transfer/futures.py", line 103, in result
    return self._coordinator.result()
  File "/home/airflow/.local/lib/python3.8/site-packages/s3transfer/futures.py", line 266, in result
    raise self._exception
  File "/home/airflow/.local/lib/python3.8/site-packages/s3transfer/tasks.py", line 269, in _main
    self._submit(transfer_future=transfer_future, **kwargs)
  File "/home/airflow/.local/lib/python3.8/site-packages/s3transfer/download.py", line 354, in _submit
    response = client.head_object(
  File "/home/airflow/.local/lib/python3.8/site-packages/botocore/client.py", line 553, in _api_call
    return self._make_api_call(operation_name, kwargs)
  File "/home/airflow/.local/lib/python3.8/site-packages/botocore/client.py", line 1009, in _make_api_call
    raise error_class(parsed_response, operation_name)
botocore.exceptions.ClientError: An error occurred (404) when calling the HeadObject operation: Not Found
[2025-09-02T06:33:31.379+0000] {taskinstance.py:2698} ERROR - Task failed with exception
Traceback (most recent call last):
  File "/opt/airflow/dags/etl_pipeline.py", line 74, in perform_extract
    client.download_file(MINIO_LANDING_BUCKET, file_path, staging_path)
  File "/home/airflow/.local/lib/python3.8/site-packages/boto3/s3/inject.py", line 192, in download_file
    return transfer.download_file(
  File "/home/airflow/.local/lib/python3.8/site-packages/boto3/s3/transfer.py", line 405, in download_file
    future.result()
  File "/home/airflow/.local/lib/python3.8/site-packages/s3transfer/futures.py", line 103, in result
    return self._coordinator.result()
  File "/home/airflow/.local/lib/python3.8/site-packages/s3transfer/futures.py", line 266, in result
    raise self._exception
  File "/home/airflow/.local/lib/python3.8/site-packages/s3transfer/tasks.py", line 269, in _main
    self._submit(transfer_future=transfer_future, **kwargs)
  File "/home/airflow/.local/lib/python3.8/site-packages/s3transfer/download.py", line 354, in _submit
    response = client.head_object(
  File "/home/airflow/.local/lib/python3.8/site-packages/botocore/client.py", line 553, in _api_call
    return self._make_api_call(operation_name, kwargs)
  File "/home/airflow/.local/lib/python3.8/site-packages/botocore/client.py", line 1009, in _make_api_call
    raise error_class(parsed_response, operation_name)
botocore.exceptions.ClientError: An error occurred (404) when calling the HeadObject operation: Not Found

The above exception was the direct cause of the following exception:

Traceback (most recent call last):
  File "/home/airflow/.local/lib/python3.8/site-packages/airflow/models/taskinstance.py", line 433, in _execute_task
    result = execute_callable(context=context, **execute_callable_kwargs)
  File "/home/airflow/.local/lib/python3.8/site-packages/airflow/operators/python.py", line 199, in execute
    return_value = self.execute_callable()
  File "/home/airflow/.local/lib/python3.8/site-packages/airflow/operators/python.py", line 216, in execute_callable
    return self.python_callable(*self.op_args, **self.op_kwargs)
  File "/opt/airflow/dags/etl_pipeline.py", line 221, in run_extract
    return perform_extract(file_path=minio_key)
  File "/opt/airflow/dags/etl_pipeline.py", line 77, in perform_extract
    raise RuntimeError(f"Failed to download {MINIO_LANDING_BUCKET}/{file_path}") from e
RuntimeError: Failed to download landing/2025/09/02/58578ad7-7d53-4d5b-8543-8cc0699b601f_applicants.csv
[2025-09-02T06:33:31.655+0000] {taskinstance.py:1138} INFO - Marking task as FAILED. dag_id=etl_pipeline, task_id=extract, execution_date=20250902T063306, start_date=20250902T063329, end_date=20250902T063331
[2025-09-02T06:33:31.793+0000] {standard_task_runner.py:107} ERROR - Failed to execute job 23 for task extract (Failed to download landing/2025/09/02/58578ad7-7d53-4d5b-8543-8cc0699b601f_applicants.csv; 1033)
[2025-09-02T06:33:31.858+0000] {local_task_job_runner.py:234} INFO - Task exited with return code 1
[2025-09-02T06:33:32.002+0000] {taskinstance.py:3280} INFO - 0 downstream tasks scheduled from follow-on schedule check
