[2025-09-01T07:55:34.796+0000] {taskinstance.py:1956} INFO - Dependencies all met for dep_context=non-requeueable deps ti=<TaskInstance: etl_pipeline.load manual__2025-09-01T07:55:25.532726+00:00 [queued]>
[2025-09-01T07:55:34.931+0000] {taskinstance.py:1956} INFO - Dependencies all met for dep_context=requeueable deps ti=<TaskInstance: etl_pipeline.load manual__2025-09-01T07:55:25.532726+00:00 [queued]>
[2025-09-01T07:55:34.934+0000] {taskinstance.py:2170} INFO - Starting attempt 1 of 1
[2025-09-01T07:55:35.025+0000] {taskinstance.py:2191} INFO - Executing <Task(PythonOperator): load> on 2025-09-01 07:55:25.532726+00:00
[2025-09-01T07:55:35.085+0000] {standard_task_runner.py:60} INFO - Started process 284 to run task
[2025-09-01T07:55:35.095+0000] {standard_task_runner.py:87} INFO - Running: ['***', 'tasks', 'run', 'etl_pipeline', 'load', 'manual__2025-09-01T07:55:25.532726+00:00', '--job-id', '40', '--raw', '--subdir', 'DAGS_FOLDER/etl_pipeline.py', '--cfg-path', '/tmp/tmp8bzx343n']
[2025-09-01T07:55:35.107+0000] {standard_task_runner.py:88} INFO - Job 40: Subtask load
[2025-09-01T07:55:35.150+0000] {logging_mixin.py:188} WARNING - /home/***/.local/lib/python3.8/site-packages/***/settings.py:194 DeprecationWarning: The sql_alchemy_conn option in [core] has been moved to the sql_alchemy_conn option in [database] - the old setting has been used, but please update your config.
[2025-09-01T07:55:35.211+0000] {task_command.py:423} INFO - Running <TaskInstance: etl_pipeline.load manual__2025-09-01T07:55:25.532726+00:00 [running]> on host 0e8e106b5af3
[2025-09-01T07:55:35.325+0000] {taskinstance.py:2480} INFO - Exporting env vars: AIRFLOW_CTX_DAG_OWNER='***' AIRFLOW_CTX_DAG_ID='etl_pipeline' AIRFLOW_CTX_TASK_ID='load' AIRFLOW_CTX_EXECUTION_DATE='2025-09-01T07:55:25.532726+00:00' AIRFLOW_CTX_TRY_NUMBER='1' AIRFLOW_CTX_DAG_RUN_ID='manual__2025-09-01T07:55:25.532726+00:00'
[2025-09-01T07:55:35.339+0000] {etl_pipeline.py:137} INFO - Reading processed file /tmp/etl_processed/processed_87a6c15c-9290-4c30-9f2b-307cdeaa44c5_applicants.csv
[2025-09-01T07:55:35.388+0000] {etl_pipeline.py:161} INFO - Inserting 20 rows into ClickHouse table applicants
[2025-09-01T07:55:35.998+0000] {connection.py:411} WARNING - Failed to connect to clickhouse:9000
Traceback (most recent call last):
  File "/home/airflow/.local/lib/python3.8/site-packages/clickhouse_driver/connection.py", line 399, in connect
    return self._init_connection(host, port)
  File "/home/airflow/.local/lib/python3.8/site-packages/clickhouse_driver/connection.py", line 329, in _init_connection
    self.socket = self._create_socket(host, port)
  File "/home/airflow/.local/lib/python3.8/site-packages/clickhouse_driver/connection.py", line 280, in _create_socket
    for res in socket.getaddrinfo(host, port, 0, socket.SOCK_STREAM):
  File "/usr/local/lib/python3.8/socket.py", line 918, in getaddrinfo
    for res in _socket.getaddrinfo(host, port, family, type, proto, flags):
socket.gaierror: [Errno -2] Name or service not known
[2025-09-01T07:55:36.003+0000] {etl_pipeline.py:164} ERROR - Failed to insert into ClickHouse: Code: 210. Name or service not known (clickhouse:9000)
Traceback (most recent call last):
  File "/opt/airflow/dags/etl_pipeline.py", line 162, in perform_load
    client.execute(insert_sql, records)
  File "/home/airflow/.local/lib/python3.8/site-packages/clickhouse_driver/client.py", line 370, in execute
    with self.disconnect_on_error(query, settings):
  File "/usr/local/lib/python3.8/contextlib.py", line 113, in __enter__
    return next(self.gen)
  File "/home/airflow/.local/lib/python3.8/site-packages/clickhouse_driver/client.py", line 313, in disconnect_on_error
    self.establish_connection(settings)
  File "/home/airflow/.local/lib/python3.8/site-packages/clickhouse_driver/client.py", line 300, in establish_connection
    self.connection.force_connect()
  File "/home/airflow/.local/lib/python3.8/site-packages/clickhouse_driver/connection.py", line 258, in force_connect
    self.connect()
  File "/home/airflow/.local/lib/python3.8/site-packages/clickhouse_driver/connection.py", line 420, in connect
    raise err
clickhouse_driver.errors.NetworkError: Code: 210. Name or service not known (clickhouse:9000)
[2025-09-01T07:55:36.008+0000] {taskinstance.py:2698} ERROR - Task failed with exception
Traceback (most recent call last):
  File "/opt/airflow/dags/etl_pipeline.py", line 162, in perform_load
    client.execute(insert_sql, records)
  File "/home/airflow/.local/lib/python3.8/site-packages/clickhouse_driver/client.py", line 370, in execute
    with self.disconnect_on_error(query, settings):
  File "/usr/local/lib/python3.8/contextlib.py", line 113, in __enter__
    return next(self.gen)
  File "/home/airflow/.local/lib/python3.8/site-packages/clickhouse_driver/client.py", line 313, in disconnect_on_error
    self.establish_connection(settings)
  File "/home/airflow/.local/lib/python3.8/site-packages/clickhouse_driver/client.py", line 300, in establish_connection
    self.connection.force_connect()
  File "/home/airflow/.local/lib/python3.8/site-packages/clickhouse_driver/connection.py", line 258, in force_connect
    self.connect()
  File "/home/airflow/.local/lib/python3.8/site-packages/clickhouse_driver/connection.py", line 420, in connect
    raise err
clickhouse_driver.errors.NetworkError: Code: 210. Name or service not known (clickhouse:9000)

The above exception was the direct cause of the following exception:

Traceback (most recent call last):
  File "/home/airflow/.local/lib/python3.8/site-packages/airflow/models/taskinstance.py", line 433, in _execute_task
    result = execute_callable(context=context, **execute_callable_kwargs)
  File "/home/airflow/.local/lib/python3.8/site-packages/airflow/operators/python.py", line 199, in execute
    return_value = self.execute_callable()
  File "/home/airflow/.local/lib/python3.8/site-packages/airflow/operators/python.py", line 216, in execute_callable
    return self.python_callable(*self.op_args, **self.op_kwargs)
  File "/opt/airflow/dags/etl_pipeline.py", line 214, in run_load
    perform_load(processed_path=processed_path)
  File "/opt/airflow/dags/etl_pipeline.py", line 165, in perform_load
    raise RuntimeError(f"Load failed for {processed_path} into {CLICKHOUSE_TABLE}") from e
RuntimeError: Load failed for /tmp/etl_processed/processed_87a6c15c-9290-4c30-9f2b-307cdeaa44c5_applicants.csv into applicants
[2025-09-01T07:55:36.032+0000] {taskinstance.py:1138} INFO - Marking task as FAILED. dag_id=etl_pipeline, task_id=load, execution_date=20250901T075525, start_date=20250901T075534, end_date=20250901T075536
[2025-09-01T07:55:36.059+0000] {standard_task_runner.py:107} ERROR - Failed to execute job 40 for task load (Load failed for /tmp/etl_processed/processed_87a6c15c-9290-4c30-9f2b-307cdeaa44c5_applicants.csv into applicants; 284)
[2025-09-01T07:55:36.093+0000] {local_task_job_runner.py:234} INFO - Task exited with return code 1
[2025-09-01T07:55:36.124+0000] {taskinstance.py:3280} INFO - 0 downstream tasks scheduled from follow-on schedule check
